<?xml version="1.0"?>
<sdf version="1.7">
  <model name="Dextra_right">

    <link name="RightWrist_link">
      <pose>0 0 0 0 -0 0</pose>
      <inertial>
        <mass>0.3</mass>
      </inertial>
      <visual name="RightWrist_visual">
        <geometry>
          <mesh>
            <scale>0.001 0.001 0.001</scale>
            <uri>model://dextra_right/meshes/visual/RightStaticLinks.dae</uri>
          </mesh>
        </geometry>
        <material>
          <ambient>0.792157 0.819608 0.933333 1</ambient>
          <diffuse>0.792157 0.819608 0.933333 1</diffuse>
          <specular>0.633726 0.655686 0.746667 1</specular>
        </material>
      </visual>
      <collision name="RightWrist_collision">
        <geometry>
          <mesh>
            <scale>0.001 0.001 0.001</scale>
            <uri>model://dextra_right/meshes/collision/RightStaticLinks.stl</uri>
          </mesh>
        </geometry>
        <max_contacts>2</max_contacts>
        <surface>
          <contact>
            <ode>
              <kp>1000000</kp>
              <kd>100</kd>
              <max_vel>0.001</max_vel>
              <min_depth>0.001</min_depth>
            </ode>
          </contact>
          <friction>
            <ode>
              <mu>1</mu>
              <mu2>1</mu2>
              <slip1>0</slip1>
              <slip2>0</slip2>
            </ode>
          </friction>
        </surface>
      </collision>
    </link>

    <link name="RightThumbAbductor_link">
      <pose relative_to="RightWrist_link">0.026 -0.0126 -0.112 -1.5708 0 0</pose>
      <inertial>
        <mass>0.1</mass>
      </inertial>
      <visual name="RightThumbAbductor_visual">
        <geometry>
          <mesh>
            <scale>0.001 0.001 0.001</scale>
            <uri>model://dextra_common/meshes/visual/Abductor.dae</uri>
          </mesh>
        </geometry>
        <material>
          <ambient>0.792157 0.819608 0.933333 1</ambient>
          <diffuse>0.792157 0.819608 0.933333 1</diffuse>
          <specular>0.633726 0.655686 0.746667 1</specular>
        </material>
      </visual>
      <collision name="RightThumbAbductor_collision">
        <geometry>
          <mesh>
            <scale>0.001 0.001 0.001</scale>
            <uri>model://dextra_common/meshes/collision/Abductor.stl</uri>
          </mesh>
        </geometry>
        <max_contacts>2</max_contacts>
        <surface>
          <contact>
            <ode>
              <kp>1000000</kp>
              <kd>100</kd>
              <max_vel>0.001</max_vel>
              <min_depth>0.001</min_depth>
            </ode>
          </contact>
          <friction>
            <ode>
              <mu>1</mu>
              <mu2>1</mu2>
              <slip1>0</slip1>
              <slip2>0</slip2>
            </ode>
          </friction>
        </surface>
      </collision>
    </link>

    <joint name="RightThumbAbductor" type="revolute">
      <parent>RightWrist_link</parent>
      <child>RightThumbAbductor_link</child>
      <axis>
        <xyz>0 -1 0</xyz>
        <limit>
          <lower>0.0</lower>
          <upper>1.5708</upper>
        </limit>
        <dynamics>
          <damping>0.001</damping>
          <friction>0.7</friction>
        </dynamics>
      </axis>
    </joint>

    <link name="RightThumbProximal_link">
      <pose relative_to="RightThumbAbductor_link">0.0406 0.0685 0.01775 1.5708 0 1.5708</pose>
      <inertial>
        <mass>0.1</mass>
      </inertial>
      <visual name="RightThumbProximal_visual">
        <geometry>
          <mesh>
            <scale>0.001 0.001 0.001</scale>
            <uri>model://dextra_common/meshes/visual/ProximalThumb.dae</uri>
          </mesh>
        </geometry>
        <material>
          <ambient>0.792157 0.819608 0.933333 1</ambient>
          <diffuse>0.792157 0.819608 0.933333 1</diffuse>
          <specular>0.633726 0.655686 0.746667 1</specular>
        </material>
      </visual>
      <collision name="RightThumbProximal_collision">
        <geometry>
          <mesh>
            <scale>0.001 0.001 0.001</scale>
            <uri>model://dextra_common/meshes/collision/ProximalThumb.stl</uri>
          </mesh>
        </geometry>
        <max_contacts>2</max_contacts>
        <surface>
          <contact>
            <ode>
              <kp>1000000</kp>
              <kd>100</kd>
              <max_vel>0.001</max_vel>
              <min_depth>0.001</min_depth>
            </ode>
          </contact>
          <friction>
            <ode>
              <mu>1</mu>
              <mu2>1</mu2>
              <slip1>0</slip1>
              <slip2>0</slip2>
            </ode>
          </friction>
        </surface>
      </collision>
    </link>

    <joint name="RightThumbProximal" type="revolute">
      <parent>RightThumbAbductor_link</parent>
      <child>RightThumbProximal_link</child>
      <axis>
        <xyz>0 -1 0</xyz>
        <limit>
          <lower>-1.5708</lower>
          <upper>1.5708</upper>
        </limit>
        <dynamics>
          <damping>0.001</damping>
          <friction>0.7</friction>
        </dynamics>
      </axis>
    </joint>

    <link name="RightThumbDistal_link">
      <pose relative_to="RightThumbProximal_link">0.03 0 0 0 0 0</pose>
      <inertial>
        <mass>0.1</mass>
      </inertial>
      <visual name="RightThumbDistal_visual">
        <geometry>
          <mesh>
            <scale>0.001 0.001 0.001</scale>
            <uri>model://dextra_common/meshes/visual/DistalThumb.dae</uri>
          </mesh>
        </geometry>
        <material>
          <ambient>0.792157 0.819608 0.933333 1</ambient>
          <diffuse>0.792157 0.819608 0.933333 1</diffuse>
          <specular>0.633726 0.655686 0.746667 1</specular>
        </material>
      </visual>
      <collision name="RightThumbDistal_collision">
        <geometry>
          <mesh>
            <scale>0.001 0.001 0.001</scale>
            <uri>model://dextra_common/meshes/collision/DistalThumb.stl</uri>
          </mesh>
        </geometry>
        <max_contacts>2</max_contacts>
        <surface>
          <contact>
            <ode>
              <kp>1000000</kp>
              <kd>100</kd>
              <max_vel>0.001</max_vel>
              <min_depth>0.001</min_depth>
            </ode>
          </contact>
          <friction>
            <ode>
              <mu>1</mu>
              <mu2>1</mu2>
              <slip1>0</slip1>
              <slip2>0</slip2>
            </ode>
          </friction>
        </surface>
      </collision>
    </link>

    <joint name="RightThumbDistal" type="revolute">
      <parent>RightThumbProximal_link</parent>
      <child>RightThumbDistal_link</child>
      <axis>
        <xyz>0 -1 0</xyz>
        <limit>
          <lower>-1.48353</lower>
          <upper>-0.122173</upper>
        </limit>
        <dynamics>
          <damping>0.001</damping>
          <friction>0.7</friction>
        </dynamics>
      </axis>
      <resolution>1</resolution>
    </joint>

    <link name="RightPinkyProximal_link">
      <pose relative_to="RightWrist_link">-0.01062 -0.001 -0.196 1.5708 1.5708 0</pose>
      <inertial>
        <mass>0.1</mass>
      </inertial>
      <visual name="RightPinkyProximal_visual">
        <geometry>
          <mesh>
            <scale>0.001 0.001 0.001</scale>
            <uri>model://dextra_common/meshes/visual/Proximal.dae</uri>
          </mesh>
        </geometry>
        <material>
          <ambient>0.792157 0.819608 0.933333 1</ambient>
          <diffuse>0.792157 0.819608 0.933333 1</diffuse>
          <specular>0.633726 0.655686 0.746667 1</specular>
        </material>
      </visual>
      <collision name="RightPinkyProximal_collision">
        <geometry>
          <mesh>
            <scale>0.001 0.001 0.001</scale>
            <uri>model://dextra_common/meshes/collision/Proximal.stl</uri>
          </mesh>
        </geometry>
        <max_contacts>2</max_contacts>
        <surface>
          <contact>
            <ode>
              <kp>1000000</kp>
              <kd>100</kd>
              <max_vel>0.001</max_vel>
              <min_depth>0.001</min_depth>
            </ode>
          </contact>
          <friction>
            <ode>
              <mu>1</mu>
              <mu2>1</mu2>
              <slip1>0</slip1>
              <slip2>0</slip2>
            </ode>
          </friction>
        </surface>
      </collision>
    </link>

    <joint name="RightPinkyProximal" type="revolute">
      <parent>RightWrist_link</parent>
      <child>RightPinkyProximal_link</child>
      <axis>
        <xyz>0 -1 0</xyz>
        <limit>
          <lower>-1.48353</lower>
          <upper>-0.122173</upper>
          <velocity>0.174533</velocity>
        </limit>
        <dynamics>
          <damping>0.001</damping>
          <friction>0.7</friction>
        </dynamics>
      </axis>
    </joint>

    <link name="RightPinkyMiddle_link">
      <pose relative_to="RightPinkyProximal_link">0.035 0 0 0 0 0</pose>
      <inertial>
        <mass>0.1</mass>
      </inertial>
      <visual name="RightPinkyMiddle_visual">
        <geometry>
          <mesh>
            <scale>0.001 0.001 0.001</scale>
            <uri>model://dextra_common/meshes/visual/Middle.dae</uri>
          </mesh>
        </geometry>
        <material>
          <ambient>0.792157 0.819608 0.933333 1</ambient>
          <diffuse>0.792157 0.819608 0.933333 1</diffuse>
          <specular>0.633726 0.655686 0.746667 1</specular>
        </material>
      </visual>
      <collision name="RightPinkyMiddle_collision">
        <geometry>
          <mesh>
            <scale>0.001 0.001 0.001</scale>
            <uri>model://dextra_common/meshes/collision/Middle.stl</uri>
          </mesh>
        </geometry>
        <max_contacts>2</max_contacts>
        <surface>
          <contact>
            <ode>
              <kp>1000000</kp>
              <kd>100</kd>
              <max_vel>0.001</max_vel>
              <min_depth>0.001</min_depth>
            </ode>
          </contact>
          <friction>
            <ode>
              <mu>1</mu>
              <mu2>1</mu2>
              <slip1>0</slip1>
              <slip2>0</slip2>
            </ode>
          </friction>
        </surface>
      </collision>
    </link>

    <joint name="RightPinkyMiddle" type="revolute">
      <parent>RightPinkyProximal_link</parent>
      <child>RightPinkyMiddle_link</child>
      <axis>
        <xyz>0 -1 0</xyz>
        <limit>
          <lower>-1.48353</lower>
          <upper>-0.122173</upper>
          <velocity>0.174533</velocity>
        </limit>
        <dynamics>
          <damping>0.001</damping>
          <friction>0.7</friction>
        </dynamics>
      </axis>
    </joint>

    <link name="RightPinkyDistal_link">
      <pose relative_to="RightPinkyMiddle_link">0.025 0 0 0 0 0</pose>
      <inertial>
        <mass>0.1</mass>
      </inertial>
      <visual name="RightPinkyDistal_visual">
        <geometry>
          <mesh>
            <scale>0.001 0.001 0.001</scale>
            <uri>model://dextra_common/meshes/visual/Distal.dae</uri>
          </mesh>
        </geometry>
        <material>
          <ambient>0.792157 0.819608 0.933333 1</ambient>
          <diffuse>0.792157 0.819608 0.933333 1</diffuse>
          <specular>0.633726 0.655686 0.746667 1</specular>
        </material>
      </visual>
      <collision name="RightPinkyDistal_collision">
        <geometry>
          <mesh>
            <scale>0.001 0.001 0.001</scale>
            <uri>model://dextra_common/meshes/collision/Distal.stl</uri>
          </mesh>
        </geometry>
        <max_contacts>2</max_contacts>
        <surface>
          <contact>
            <ode>
              <kp>1000000</kp>
              <kd>100</kd>
              <max_vel>0.001</max_vel>
              <min_depth>0.001</min_depth>
            </ode>
          </contact>
          <friction>
            <ode>
              <mu>1</mu>
              <mu2>1</mu2>
              <slip1>0</slip1>
              <slip2>0</slip2>
            </ode>
          </friction>
        </surface>
      </collision>
    </link>

    <joint name="RightPinkyDistal" type="revolute">
      <parent>RightPinkyMiddle_link</parent>
      <child>RightPinkyDistal_link</child>
      <axis>
        <xyz>0 -1 0</xyz>
        <limit>
          <lower>-1.48353</lower>
          <upper>-0.122173</upper>
          <velocity>0.174533</velocity>
        </limit>
        <dynamics>
          <damping>0.001</damping>
          <friction>0.7</friction>
        </dynamics>
      </axis>
    </joint>

    <link name="RightRingProximal_link">
      <pose relative_to="RightWrist_link">0.0089 -0.001 -0.211 1.5708 1.5708 0</pose>
      <inertial>
        <mass>0.1</mass>
      </inertial>
      <visual name="RightRingProximal_visual">
        <geometry>
          <mesh>
            <scale>0.001 0.001 0.001</scale>
            <uri>model://dextra_common/meshes/visual/Proximal.dae</uri>
          </mesh>
        </geometry>
        <material>
          <ambient>0.792157 0.819608 0.933333 1</ambient>
          <diffuse>0.792157 0.819608 0.933333 1</diffuse>
          <specular>0.633726 0.655686 0.746667 1</specular>
        </material>
      </visual>
      <collision name="RightRingProximal_collision">
        <geometry>
          <mesh>
            <scale>0.001 0.001 0.001</scale>
            <uri>model://dextra_common/meshes/collision/Proximal.stl</uri>
          </mesh>
        </geometry>
        <max_contacts>2</max_contacts>
        <surface>
          <contact>
            <ode>
              <kp>1000000</kp>
              <kd>100</kd>
              <max_vel>0.001</max_vel>
              <min_depth>0.001</min_depth>
            </ode>
          </contact>
          <friction>
            <ode>
              <mu>1</mu>
              <mu2>1</mu2>
              <slip1>0</slip1>
              <slip2>0</slip2>
            </ode>
          </friction>
        </surface>
      </collision>
    </link>

    <joint name="RightRingProximal" type="revolute">
      <parent>RightWrist_link</parent>
      <child>RightRingProximal_link</child>
      <axis>
        <xyz>0 -1 0</xyz>
        <limit>
          <lower>-1.48353</lower>
          <upper>-0.122173</upper>
          <velocity>0.174533</velocity>
        </limit>
        <dynamics>
          <damping>0.001</damping>
          <friction>0.7</friction>
        </dynamics>
      </axis>
    </joint>

    <link name="RightRingMiddle_link">
      <pose relative_to="RightRingProximal_link">0.035 0 0 0 0 0</pose>
      <inertial>
        <mass>0.1</mass>
      </inertial>
      <visual name="RightRingMiddle_visual">
        <geometry>
          <mesh>
            <scale>0.001 0.001 0.001</scale>
            <uri>model://dextra_common/meshes/visual/Middle.dae</uri>
          </mesh>
        </geometry>
        <material>
          <ambient>0.792157 0.819608 0.933333 1</ambient>
          <diffuse>0.792157 0.819608 0.933333 1</diffuse>
          <specular>0.633726 0.655686 0.746667 1</specular>
        </material>
      </visual>
      <collision name="RightRingMiddle_collision">
        <geometry>
          <mesh>
            <scale>0.001 0.001 0.001</scale>
            <uri>model://dextra_common/meshes/collision/Middle.stl</uri>
          </mesh>
        </geometry>
        <max_contacts>2</max_contacts>
        <surface>
          <contact>
            <ode>
              <kp>1000000</kp>
              <kd>100</kd>
              <max_vel>0.001</max_vel>
              <min_depth>0.001</min_depth>
            </ode>
          </contact>
          <friction>
            <ode>
              <mu>1</mu>
              <mu2>1</mu2>
              <slip1>0</slip1>
              <slip2>0</slip2>
            </ode>
          </friction>
        </surface>
      </collision>
    </link>

    <joint name="RightRingMiddle" type="revolute">
      <parent>RightRingProximal_link</parent>
      <child>RightRingMiddle_link</child>
      <axis>
        <xyz>0 -1 0</xyz>
        <limit>
          <lower>-1.48353</lower>
          <upper>-0.122173</upper>
          <velocity>0.174533</velocity>
        </limit>
        <dynamics>
          <damping>0.001</damping>
          <friction>0.7</friction>
        </dynamics>
      </axis>
    </joint>

    <link name="RightRingDistal_link">
      <pose relative_to="RightRingMiddle_link">0.025 0 0 0 0 0</pose>
      <inertial>
        <mass>0.1</mass>
      </inertial>
      <visual name="RightRingDistal_visual">
        <geometry>
          <mesh>
            <scale>0.001 0.001 0.001</scale>
            <uri>model://dextra_common/meshes/visual/Distal.dae</uri>
          </mesh>
        </geometry>
        <material>
          <ambient>0.792157 0.819608 0.933333 1</ambient>
          <diffuse>0.792157 0.819608 0.933333 1</diffuse>
          <specular>0.633726 0.655686 0.746667 1</specular>
        </material>
      </visual>
      <collision name="RightRingDistal_collision">
        <geometry>
          <mesh>
            <scale>0.001 0.001 0.001</scale>
            <uri>model://dextra_common/meshes/collision/Distal.stl</uri>
          </mesh>
        </geometry>
        <max_contacts>2</max_contacts>
        <surface>
          <contact>
            <ode>
              <kp>1000000</kp>
              <kd>100</kd>
              <max_vel>0.001</max_vel>
              <min_depth>0.001</min_depth>
            </ode>
          </contact>
          <friction>
            <ode>
              <mu>1</mu>
              <mu2>1</mu2>
              <slip1>0</slip1>
              <slip2>0</slip2>
            </ode>
          </friction>
        </surface>
      </collision>
    </link>

    <joint name="RightRingDistal" type="revolute">
      <parent>RightRingMiddle_link</parent>
      <child>RightRingDistal_link</child>
      <axis>
        <xyz>0 -1 0</xyz>
        <limit>
          <lower>-1.48353</lower>
          <upper>-0.122173</upper>
          <velocity>0.174533</velocity>
        </limit>
        <dynamics>
          <damping>0.001</damping>
          <friction>0.7</friction>
        </dynamics>
      </axis>
    </joint>

    <link name="RightMiddleProximal_link">
      <pose relative_to="RightWrist_link">0.02842 -0.001 -0.221 1.5708 1.5708 0</pose>
      <inertial>
        <mass>0.1</mass>
      </inertial>
      <visual name="RightMiddleProximal_visual">
        <geometry>
          <mesh>
            <scale>0.001 0.001 0.001</scale>
            <uri>model://dextra_common/meshes/visual/Proximal.dae</uri>
          </mesh>
        </geometry>
        <material>
          <ambient>0.792157 0.819608 0.933333 1</ambient>
          <diffuse>0.792157 0.819608 0.933333 1</diffuse>
          <specular>0.633726 0.655686 0.746667 1</specular>
        </material>
      </visual>
      <collision name="RightMiddleProximal_collision">
        <geometry>
          <mesh>
            <scale>0.001 0.001 0.001</scale>
            <uri>model://dextra_common/meshes/collision/Proximal.stl</uri>
          </mesh>
        </geometry>
        <max_contacts>2</max_contacts>
        <surface>
          <contact>
            <ode>
              <kp>1000000</kp>
              <kd>100</kd>
              <max_vel>0.001</max_vel>
              <min_depth>0.001</min_depth>
            </ode>
          </contact>
          <friction>
            <ode>
              <mu>1</mu>
              <mu2>1</mu2>
              <slip1>0</slip1>
              <slip2>0</slip2>
            </ode>
          </friction>
        </surface>
      </collision>
    </link>

    <joint name="RightMiddleProximal" type="revolute">
      <parent>RightWrist_link</parent>
      <child>RightMiddleProximal_link</child>
      <axis>
        <xyz>0 -1 0</xyz>
        <limit>
          <lower>-1.48353</lower>
          <upper>-0.122173</upper>
          <velocity>0.174533</velocity>
        </limit>
        <dynamics>
          <damping>0.001</damping>
          <friction>0.7</friction>
        </dynamics>
      </axis>
    </joint>

    <link name="RightMiddleMiddle_link">
      <pose relative_to="RightMiddleProximal_link">0.035 0 0 0 0 0</pose>
      <inertial>
        <mass>0.1</mass>
      </inertial>
      <visual name="RightMiddleMiddle_visual">
        <geometry>
          <mesh>
            <scale>0.001 0.001 0.001</scale>
            <uri>model://dextra_common/meshes/visual/Middle.dae</uri>
          </mesh>
        </geometry>
        <material>
          <ambient>0.792157 0.819608 0.933333 1</ambient>
          <diffuse>0.792157 0.819608 0.933333 1</diffuse>
          <specular>0.633726 0.655686 0.746667 1</specular>
        </material>
      </visual>
      <collision name="RightMiddleMiddle_collision">
        <geometry>
          <mesh>
            <scale>0.001 0.001 0.001</scale>
            <uri>model://dextra_common/meshes/collision/Middle.stl</uri>
          </mesh>
        </geometry>
        <max_contacts>2</max_contacts>
        <surface>
          <contact>
            <ode>
              <kp>1000000</kp>
              <kd>100</kd>
              <max_vel>0.001</max_vel>
              <min_depth>0.001</min_depth>
            </ode>
          </contact>
          <friction>
            <ode>
              <mu>1</mu>
              <mu2>1</mu2>
              <slip1>0</slip1>
              <slip2>0</slip2>
            </ode>
          </friction>
        </surface>
      </collision>
    </link>

    <joint name="RightMiddleMiddle" type="revolute">
      <parent>RightMiddleProximal_link</parent>
      <child>RightMiddleMiddle_link</child>
      <axis>
        <xyz>0 -1 0</xyz>
        <limit>
          <lower>-1.48353</lower>
          <upper>-0.122173</upper>
          <velocity>0.174533</velocity>
        </limit>
        <dynamics>
          <damping>0.001</damping>
          <friction>0.7</friction>
        </dynamics>
      </axis>
    </joint>

    <link name="RightMiddleDistal_link">
      <pose relative_to="RightMiddleMiddle_link">0.025 0 0 0 0 0</pose>
      <inertial>
        <mass>0.1</mass>
      </inertial>
      <visual name="RightMiddleDistal_visual">
        <geometry>
          <mesh>
            <scale>0.001 0.001 0.001</scale>
            <uri>model://dextra_common/meshes/visual/Distal.dae</uri>
          </mesh>
        </geometry>
        <material>
          <ambient>0.792157 0.819608 0.933333 1</ambient>
          <diffuse>0.792157 0.819608 0.933333 1</diffuse>
          <specular>0.633726 0.655686 0.746667 1</specular>
        </material>
      </visual>
      <collision name="RightMiddleDistal_collision">
        <geometry>
          <mesh>
            <scale>0.001 0.001 0.001</scale>
            <uri>model://dextra_common/meshes/collision/Distal.stl</uri>
          </mesh>
        </geometry>
        <max_contacts>2</max_contacts>
        <surface>
          <contact>
            <ode>
              <kp>1000000</kp>
              <kd>100</kd>
              <max_vel>0.001</max_vel>
              <min_depth>0.001</min_depth>
            </ode>
          </contact>
          <friction>
            <ode>
              <mu>1</mu>
              <mu2>1</mu2>
              <slip1>0</slip1>
              <slip2>0</slip2>
            </ode>
          </friction>
        </surface>
      </collision>
    </link>

    <joint name="RightMiddleDistal" type="revolute">
      <parent>RightMiddleMiddle_link</parent>
      <child>RightMiddleDistal_link</child>
      <axis>
        <xyz>0 -1 0</xyz>
        <limit>
          <lower>-1.48353</lower>
          <upper>-0.122173</upper>
          <velocity>0.174533</velocity>
        </limit>
        <dynamics>
          <damping>0.001</damping>
          <friction>0.7</friction>
        </dynamics>
      </axis>
    </joint>

    <link name="RightIndexProximal_link">
      <pose relative_to="RightWrist_link">0.04794 -0.001 -0.213 1.5708 1.5708 0</pose>
      <inertial>
        <mass>0.1</mass>
      </inertial>
      <visual name="RightIndexProximal_visual">
        <geometry>
          <mesh>
            <scale>0.001 0.001 0.001</scale>
            <uri>model://dextra_common/meshes/visual/Proximal.dae</uri>
          </mesh>
        </geometry>
        <material>
          <ambient>0.792157 0.819608 0.933333 1</ambient>
          <diffuse>0.792157 0.819608 0.933333 1</diffuse>
          <specular>0.633726 0.655686 0.746667 1</specular>
        </material>
      </visual>
      <collision name="RightIndexProximal_collision">
        <geometry>
          <mesh>
            <scale>0.001 0.001 0.001</scale>
            <uri>model://dextra_common/meshes/collision/Proximal.stl</uri>
          </mesh>
        </geometry>
        <max_contacts>2</max_contacts>
        <surface>
          <contact>
            <ode>
              <kp>1000000</kp>
              <kd>100</kd>
              <max_vel>0.001</max_vel>
              <min_depth>0.001</min_depth>
            </ode>
          </contact>
          <friction>
            <ode>
              <mu>1</mu>
              <mu2>1</mu2>
              <slip1>0</slip1>
              <slip2>0</slip2>
            </ode>
          </friction>
        </surface>
      </collision>
    </link>

    <joint name="RightIndexProximal" type="revolute">
      <parent>RightWrist_link</parent>
      <child>RightIndexProximal_link</child>
      <axis>
        <xyz>0 -1 0</xyz>
        <limit>
          <lower>-1.48353</lower>
          <upper>-0.122173</upper>
          <velocity>0.174533</velocity>
        </limit>
        <dynamics>
          <damping>0.001</damping>
          <friction>0.7</friction>
        </dynamics>
      </axis>
    </joint>

    <link name="RightIndexMiddle_link">
      <pose relative_to="RightIndexProximal_link">0.035 0 0 0 0 0</pose>
      <inertial>
        <mass>0.1</mass>
      </inertial>
      <visual name="RightIndexMiddle_visual">
        <geometry>
          <mesh>
            <scale>0.001 0.001 0.001</scale>
            <uri>model://dextra_common/meshes/visual/Middle.dae</uri>
          </mesh>
        </geometry>
        <material>
          <ambient>0.792157 0.819608 0.933333 1</ambient>
          <diffuse>0.792157 0.819608 0.933333 1</diffuse>
          <specular>0.633726 0.655686 0.746667 1</specular>
        </material>
      </visual>
      <collision name="RightIndexMiddle_collision">
        <geometry>
          <mesh>
            <scale>0.001 0.001 0.001</scale>
            <uri>model://dextra_common/meshes/collision/Middle.stl</uri>
          </mesh>
        </geometry>
        <max_contacts>2</max_contacts>
        <surface>
          <contact>
            <ode>
              <kp>1000000</kp>
              <kd>100</kd>
              <max_vel>0.001</max_vel>
              <min_depth>0.001</min_depth>
            </ode>
          </contact>
          <friction>
            <ode>
              <mu>1</mu>
              <mu2>1</mu2>
              <slip1>0</slip1>
              <slip2>0</slip2>
            </ode>
          </friction>
        </surface>
      </collision>
    </link>

    <joint name="RightIndexMiddle" type="revolute">
      <parent>RightIndexProximal_link</parent>
      <child>RightIndexMiddle_link</child>
      <axis>
        <xyz>0 -1 0</xyz>
        <limit>
          <lower>-1.48353</lower>
          <upper>-0.122173</upper>
          <velocity>0.174533</velocity>
        </limit>
        <dynamics>
          <damping>0.001</damping>
          <friction>0.7</friction>
        </dynamics>
      </axis>
    </joint>

    <link name="RightIndexDistal_link">
      <pose relative_to="RightIndexMiddle_link">0.025 0 0 0 0 0</pose>
      <inertial>
        <mass>0.1</mass>
      </inertial>
      <visual name="RightIndexDistal_visual">
        <geometry>
          <mesh>
            <scale>0.001 0.001 0.001</scale>
            <uri>model://dextra_common/meshes/visual/Distal.dae</uri>
          </mesh>
        </geometry>
        <material>
          <ambient>0.792157 0.819608 0.933333 1</ambient>
          <diffuse>0.792157 0.819608 0.933333 1</diffuse>
          <specular>0.633726 0.655686 0.746667 1</specular>
        </material>
      </visual>
      <collision name="RightIndexDistal_collision">
        <geometry>
          <mesh>
            <scale>0.001 0.001 0.001</scale>
            <uri>model://dextra_common/meshes/collision/Distal.stl</uri>
          </mesh>
        </geometry>
        <max_contacts>2</max_contacts>
        <surface>
          <contact>
            <ode>
              <kp>1000000</kp>
              <kd>100</kd>
              <max_vel>0.001</max_vel>
              <min_depth>0.001</min_depth>
            </ode>
          </contact>
          <friction>
            <ode>
              <mu>1</mu>
              <mu2>1</mu2>
              <slip1>0</slip1>
              <slip2>0</slip2>
            </ode>
          </friction>
        </surface>
      </collision>
    </link>

    <joint name="RightIndexDistal" type="revolute">
      <parent>RightIndexMiddle_link</parent>
      <child>RightIndexDistal_link</child>
      <axis>
        <xyz>0 -1 0</xyz>
        <limit>
          <lower>-1.48353</lower>
          <upper>-0.122173</upper>
          <velocity>0.174533</velocity>
        </limit>
        <dynamics>
          <damping>0.001</damping>
          <friction>0.7</friction>
        </dynamics>
      </axis>
    </joint>

    <plugin name="gzyarp::ControlBoard" filename="gz-sim-yarp-controlboard-system">
      <yarpConfigurationFile>model://dextra_right/conf/gazebo_dextra_right.ini</yarpConfigurationFile>
    </plugin>

    <plugin name="gzyarp::RobotInterface" filename="gz-sim-yarp-robotinterface-system">
      <yarpRobotInterfaceConfigurationFile>model://dextra_right/conf/dextra_right_nws_yarp.xml</yarpRobotInterfaceConfigurationFile>
    </plugin>

    <plugin name="gzyarp::RobotInterface" filename="gz-sim-yarp-robotinterface-system">
      <yarpRobotInterfaceConfigurationFile>model://dextra_right/conf/dextra_right_nws_ros2.xml</yarpRobotInterfaceConfigurationFile>
    </plugin>

  </model>
</sdf>
