<?xml version="1.0"?>
<sdf version="1.7">
  <model name="TEO_leftDextra">

    <link name="LeftWrist_link">
      <pose>0 0 0 0 -0 0</pose>
      <inertial>
        <mass>0.3</mass>
      </inertial>
      <visual name="LeftWrist_visual">
        <geometry>
          <mesh>
            <scale>0.001 0.001 0.001</scale>
            <uri>model://teo_dextra/meshes/visual/LeftStaticLinks.dae</uri>
          </mesh>
        </geometry>
        <material>
          <ambient>0.792157 0.819608 0.933333 1</ambient>
          <diffuse>0.792157 0.819608 0.933333 1</diffuse>
          <specular>0.633726 0.655686 0.746667 1</specular>
        </material>
      </visual>
      <collision name="LeftWrist_collision">
        <geometry>
          <mesh>
            <scale>0.001 0.001 0.001</scale>
            <uri>model://teo_dextra/meshes/collision/LeftStaticLinks.stl</uri>
          </mesh>
        </geometry>
        <max_contacts>2</max_contacts>
        <surface>
          <contact>
            <ode>
              <kp>1000000</kp>
              <kd>100</kd>
              <max_vel>0.001</max_vel>
              <min_depth>0.001</min_depth>
            </ode>
          </contact>
          <friction>
            <ode>
              <mu>1</mu>
              <mu2>1</mu2>
              <slip1>0</slip1>
              <slip2>0</slip2>
            </ode>
          </friction>
        </surface>
      </collision>
    </link>

    <link name="LeftThumbAbductor_link">
      <pose relative_to="LeftWrist_link">0.026 -0.0126 -0.112 -1.5708 0 0</pose>
      <inertial>
        <mass>0.1</mass>
      </inertial>
      <visual name="LeftThumbAbductor_visual">
        <geometry>
          <mesh>
            <scale>0.001 0.001 0.001</scale>
            <uri>model://teo_dextra/meshes/visual/Abductor.dae</uri>
          </mesh>
        </geometry>
        <material>
          <ambient>0.792157 0.819608 0.933333 1</ambient>
          <diffuse>0.792157 0.819608 0.933333 1</diffuse>
          <specular>0.633726 0.655686 0.746667 1</specular>
        </material>
      </visual>
      <collision name="LeftThumbAbductor_collision">
        <geometry>
          <mesh>
            <scale>0.001 0.001 0.001</scale>
            <uri>model://teo_dextra/meshes/collision/Abductor.stl</uri>
          </mesh>
        </geometry>
        <max_contacts>2</max_contacts>
        <surface>
          <contact>
            <ode>
              <kp>1000000</kp>
              <kd>100</kd>
              <max_vel>0.001</max_vel>
              <min_depth>0.001</min_depth>
            </ode>
          </contact>
          <friction>
            <ode>
              <mu>1</mu>
              <mu2>1</mu2>
              <slip1>0</slip1>
              <slip2>0</slip2>
            </ode>
          </friction>
        </surface>
      </collision>
    </link>

    <joint name="LeftThumbAbductor" type="revolute">
      <parent>LeftWrist_link</parent>
      <child>LeftThumbAbductor_link</child>
      <axis>
        <xyz>0 -1 0</xyz>
        <limit>
          <lower>-1.5708</lower>
          <upper>0.0</upper>
        </limit>
        <dynamics>
          <damping>0.001</damping>
          <friction>0.7</friction>
        </dynamics>
      </axis>
    </joint>

    <link name="LeftThumbProximal_link">
      <pose relative_to="LeftThumbAbductor_link">0.0406 0.0685 0.01775 1.5708 0 1.5708</pose>
      <inertial>
        <mass>0.1</mass>
      </inertial>
      <visual name="LeftThumbProximal_visual">
        <geometry>
          <mesh>
            <scale>0.001 0.001 0.001</scale>
            <uri>model://teo_dextra/meshes/visual/ProximalThumb.dae</uri>
          </mesh>
        </geometry>
        <material>
          <ambient>0.792157 0.819608 0.933333 1</ambient>
          <diffuse>0.792157 0.819608 0.933333 1</diffuse>
          <specular>0.633726 0.655686 0.746667 1</specular>
        </material>
      </visual>
      <collision name="LeftThumbProximal_collision">
        <geometry>
          <mesh>
            <scale>0.001 0.001 0.001</scale>
            <uri>model://teo_dextra/meshes/collision/ProximalThumb.stl</uri>
          </mesh>
        </geometry>
        <max_contacts>2</max_contacts>
        <surface>
          <contact>
            <ode>
              <kp>1000000</kp>
              <kd>100</kd>
              <max_vel>0.001</max_vel>
              <min_depth>0.001</min_depth>
            </ode>
          </contact>
          <friction>
            <ode>
              <mu>1</mu>
              <mu2>1</mu2>
              <slip1>0</slip1>
              <slip2>0</slip2>
            </ode>
          </friction>
        </surface>
      </collision>
    </link>

    <joint name="LeftThumbProximal" type="revolute">
      <parent>LeftThumbAbductor_link</parent>
      <child>LeftThumbProximal_link</child>
      <axis>
        <xyz>0 -1 0</xyz>
        <limit>
          <lower>-1.5708</lower>
          <upper>1.5708</upper>
        </limit>
        <dynamics>
          <damping>0.001</damping>
          <friction>0.7</friction>
        </dynamics>
      </axis>
    </joint>

    <link name="LeftThumbDistal_link">
      <pose relative_to="LeftThumbProximal_link">0.03 0 0 0 0 0</pose>
      <inertial>
        <mass>0.1</mass>
      </inertial>
      <visual name="LeftThumbDistal_visual">
        <geometry>
          <mesh>
            <scale>0.001 0.001 0.001</scale>
            <uri>model://teo_dextra/meshes/visual/DistalThumb.dae</uri>
          </mesh>
        </geometry>
        <material>
          <ambient>0.792157 0.819608 0.933333 1</ambient>
          <diffuse>0.792157 0.819608 0.933333 1</diffuse>
          <specular>0.633726 0.655686 0.746667 1</specular>
        </material>
      </visual>
      <collision name="LeftThumbDistal_collision">
        <geometry>
          <mesh>
            <scale>0.001 0.001 0.001</scale>
            <uri>model://teo_dextra/meshes/collision/DistalThumb.stl</uri>
          </mesh>
        </geometry>
        <max_contacts>2</max_contacts>
        <surface>
          <contact>
            <ode>
              <kp>1000000</kp>
              <kd>100</kd>
              <max_vel>0.001</max_vel>
              <min_depth>0.001</min_depth>
            </ode>
          </contact>
          <friction>
            <ode>
              <mu>1</mu>
              <mu2>1</mu2>
              <slip1>0</slip1>
              <slip2>0</slip2>
            </ode>
          </friction>
        </surface>
      </collision>
    </link>

    <joint name="LeftThumbDistal" type="revolute">
      <parent>LeftThumbProximal_link</parent>
      <child>LeftThumbDistal_link</child>
      <axis>
        <xyz>0 -1 0</xyz>
        <limit>
          <lower>-1.48353</lower>
          <upper>-0.122173</upper>
        </limit>
        <dynamics>
          <damping>0.001</damping>
          <friction>0.7</friction>
        </dynamics>
      </axis>
      <resolution>1</resolution>
    </joint>

    <link name="LeftPinkyProximal_link">
      <pose relative_to="LeftWrist_link">-0.0275 0.001 -0.196 1.5708 1.5708 3.1416</pose>
      <inertial>
        <mass>0.1</mass>
      </inertial>
      <visual name="LeftPinkyProximal_visual">
        <geometry>
          <mesh>
            <scale>0.001 0.001 0.001</scale>
            <uri>model://teo_dextra/meshes/visual/Proximal.dae</uri>
          </mesh>
        </geometry>
        <material>
          <ambient>0.792157 0.819608 0.933333 1</ambient>
          <diffuse>0.792157 0.819608 0.933333 1</diffuse>
          <specular>0.633726 0.655686 0.746667 1</specular>
        </material>
      </visual>
      <collision name="LeftPinkyProximal_collision">
        <geometry>
          <mesh>
            <scale>0.001 0.001 0.001</scale>
            <uri>model://teo_dextra/meshes/collision/Proximal.stl</uri>
          </mesh>
        </geometry>
        <max_contacts>2</max_contacts>
        <surface>
          <contact>
            <ode>
              <kp>1000000</kp>
              <kd>100</kd>
              <max_vel>0.001</max_vel>
              <min_depth>0.001</min_depth>
            </ode>
          </contact>
          <friction>
            <ode>
              <mu>1</mu>
              <mu2>1</mu2>
              <slip1>0</slip1>
              <slip2>0</slip2>
            </ode>
          </friction>
        </surface>
      </collision>
    </link>

    <joint name="LeftPinkyProximal" type="revolute">
      <parent>LeftWrist_link</parent>
      <child>LeftPinkyProximal_link</child>
      <axis>
        <xyz>0 -1 0</xyz>
        <limit>
          <lower>-1.48353</lower>
          <upper>-0.122173</upper>
          <velocity>0.174533</velocity>
        </limit>
        <dynamics>
          <damping>0.001</damping>
          <friction>0.7</friction>
        </dynamics>
      </axis>
    </joint>

    <link name="LeftPinkyMiddle_link">
      <pose relative_to="LeftPinkyProximal_link">0.035 0 0 0 0 0</pose>
      <inertial>
        <mass>0.1</mass>
      </inertial>
      <visual name="LeftPinkyMiddle_visual">
        <geometry>
          <mesh>
            <scale>0.001 0.001 0.001</scale>
            <uri>model://teo_dextra/meshes/visual/Middle.dae</uri>
          </mesh>
        </geometry>
        <material>
          <ambient>0.792157 0.819608 0.933333 1</ambient>
          <diffuse>0.792157 0.819608 0.933333 1</diffuse>
          <specular>0.633726 0.655686 0.746667 1</specular>
        </material>
      </visual>
      <collision name="LeftPinkyMiddle_collision">
        <geometry>
          <mesh>
            <scale>0.001 0.001 0.001</scale>
            <uri>model://teo_dextra/meshes/collision/Middle.stl</uri>
          </mesh>
        </geometry>
        <max_contacts>2</max_contacts>
        <surface>
          <contact>
            <ode>
              <kp>1000000</kp>
              <kd>100</kd>
              <max_vel>0.001</max_vel>
              <min_depth>0.001</min_depth>
            </ode>
          </contact>
          <friction>
            <ode>
              <mu>1</mu>
              <mu2>1</mu2>
              <slip1>0</slip1>
              <slip2>0</slip2>
            </ode>
          </friction>
        </surface>
      </collision>
    </link>

    <joint name="LeftPinkyMiddle" type="revolute">
      <parent>LeftPinkyProximal_link</parent>
      <child>LeftPinkyMiddle_link</child>
      <axis>
        <xyz>0 -1 0</xyz>
        <limit>
          <lower>-1.48353</lower>
          <upper>-0.122173</upper>
          <velocity>0.174533</velocity>
        </limit>
        <dynamics>
          <damping>0.001</damping>
          <friction>0.7</friction>
        </dynamics>
      </axis>
    </joint>

    <link name="LeftPinkyDistal_link">
      <pose relative_to="LeftPinkyMiddle_link">0.025 0 0 0 0 0</pose>
      <inertial>
        <mass>0.1</mass>
      </inertial>
      <visual name="LeftPinkyDistal_visual">
        <geometry>
          <mesh>
            <scale>0.001 0.001 0.001</scale>
            <uri>model://teo_dextra/meshes/visual/Distal.dae</uri>
          </mesh>
        </geometry>
        <material>
          <ambient>0.792157 0.819608 0.933333 1</ambient>
          <diffuse>0.792157 0.819608 0.933333 1</diffuse>
          <specular>0.633726 0.655686 0.746667 1</specular>
        </material>
      </visual>
      <collision name="LeftPinkyDistal_collision">
        <geometry>
          <mesh>
            <scale>0.001 0.001 0.001</scale>
            <uri>model://teo_dextra/meshes/collision/Distal.stl</uri>
          </mesh>
        </geometry>
        <max_contacts>2</max_contacts>
        <surface>
          <contact>
            <ode>
              <kp>1000000</kp>
              <kd>100</kd>
              <max_vel>0.001</max_vel>
              <min_depth>0.001</min_depth>
            </ode>
          </contact>
          <friction>
            <ode>
              <mu>1</mu>
              <mu2>1</mu2>
              <slip1>0</slip1>
              <slip2>0</slip2>
            </ode>
          </friction>
        </surface>
      </collision>
    </link>

    <joint name="LeftPinkyDistal" type="revolute">
      <parent>LeftPinkyMiddle_link</parent>
      <child>LeftPinkyDistal_link</child>
      <axis>
        <xyz>0 -1 0</xyz>
        <limit>
          <lower>-1.48353</lower>
          <upper>-0.122173</upper>
          <velocity>0.174533</velocity>
        </limit>
        <dynamics>
          <damping>0.001</damping>
          <friction>0.7</friction>
        </dynamics>
      </axis>
    </joint>

    <link name="LeftRingProximal_link">
      <pose relative_to="LeftWrist_link">-0.00798 0.001 -0.211 1.5708 1.5708 3.1416</pose>
      <inertial>
        <mass>0.1</mass>
      </inertial>
      <visual name="LeftRingProximal_visual">
        <geometry>
          <mesh>
            <scale>0.001 0.001 0.001</scale>
            <uri>model://teo_dextra/meshes/visual/Proximal.dae</uri>
          </mesh>
        </geometry>
        <material>
          <ambient>0.792157 0.819608 0.933333 1</ambient>
          <diffuse>0.792157 0.819608 0.933333 1</diffuse>
          <specular>0.633726 0.655686 0.746667 1</specular>
        </material>
      </visual>
      <collision name="LeftRingProximal_collision">
        <geometry>
          <mesh>
            <scale>0.001 0.001 0.001</scale>
            <uri>model://teo_dextra/meshes/collision/Proximal.stl</uri>
          </mesh>
        </geometry>
        <max_contacts>2</max_contacts>
        <surface>
          <contact>
            <ode>
              <kp>1000000</kp>
              <kd>100</kd>
              <max_vel>0.001</max_vel>
              <min_depth>0.001</min_depth>
            </ode>
          </contact>
          <friction>
            <ode>
              <mu>1</mu>
              <mu2>1</mu2>
              <slip1>0</slip1>
              <slip2>0</slip2>
            </ode>
          </friction>
        </surface>
      </collision>
    </link>

    <joint name="LeftRingProximal" type="revolute">
      <parent>LeftWrist_link</parent>
      <child>LeftRingProximal_link</child>
      <axis>
        <xyz>0 -1 0</xyz>
        <limit>
          <lower>-1.48353</lower>
          <upper>-0.122173</upper>
          <velocity>0.174533</velocity>
        </limit>
        <dynamics>
          <damping>0.001</damping>
          <friction>0.7</friction>
        </dynamics>
      </axis>
    </joint>

    <link name="LeftRingMiddle_link">
      <pose relative_to="LeftRingProximal_link">0.035 0 0 0 0 0</pose>
      <inertial>
        <mass>0.1</mass>
      </inertial>
      <visual name="LeftRingMiddle_visual">
        <geometry>
          <mesh>
            <scale>0.001 0.001 0.001</scale>
            <uri>model://teo_dextra/meshes/visual/Middle.dae</uri>
          </mesh>
        </geometry>
        <material>
          <ambient>0.792157 0.819608 0.933333 1</ambient>
          <diffuse>0.792157 0.819608 0.933333 1</diffuse>
          <specular>0.633726 0.655686 0.746667 1</specular>
        </material>
      </visual>
      <collision name="LeftRingMiddle_collision">
        <geometry>
          <mesh>
            <scale>0.001 0.001 0.001</scale>
            <uri>model://teo_dextra/meshes/collision/Middle.stl</uri>
          </mesh>
        </geometry>
        <max_contacts>2</max_contacts>
        <surface>
          <contact>
            <ode>
              <kp>1000000</kp>
              <kd>100</kd>
              <max_vel>0.001</max_vel>
              <min_depth>0.001</min_depth>
            </ode>
          </contact>
          <friction>
            <ode>
              <mu>1</mu>
              <mu2>1</mu2>
              <slip1>0</slip1>
              <slip2>0</slip2>
            </ode>
          </friction>
        </surface>
      </collision>
    </link>

    <joint name="LeftRingMiddle" type="revolute">
      <parent>LeftRingProximal_link</parent>
      <child>LeftRingMiddle_link</child>
      <axis>
        <xyz>0 -1 0</xyz>
        <limit>
          <lower>-1.48353</lower>
          <upper>-0.122173</upper>
          <velocity>0.174533</velocity>
        </limit>
        <dynamics>
          <damping>0.001</damping>
          <friction>0.7</friction>
        </dynamics>
      </axis>
    </joint>

    <link name="LeftRingDistal_link">
      <pose relative_to="LeftRingMiddle_link">0.025 0 0 0 0 0</pose>
      <inertial>
        <mass>0.1</mass>
      </inertial>
      <visual name="LeftRingDistal_visual">
        <geometry>
          <mesh>
            <scale>0.001 0.001 0.001</scale>
            <uri>model://teo_dextra/meshes/visual/Distal.dae</uri>
          </mesh>
        </geometry>
        <material>
          <ambient>0.792157 0.819608 0.933333 1</ambient>
          <diffuse>0.792157 0.819608 0.933333 1</diffuse>
          <specular>0.633726 0.655686 0.746667 1</specular>
        </material>
      </visual>
      <collision name="LeftRingDistal_collision">
        <geometry>
          <mesh>
            <scale>0.001 0.001 0.001</scale>
            <uri>model://teo_dextra/meshes/collision/Distal.stl</uri>
          </mesh>
        </geometry>
        <max_contacts>2</max_contacts>
        <surface>
          <contact>
            <ode>
              <kp>1000000</kp>
              <kd>100</kd>
              <max_vel>0.001</max_vel>
              <min_depth>0.001</min_depth>
            </ode>
          </contact>
          <friction>
            <ode>
              <mu>1</mu>
              <mu2>1</mu2>
              <slip1>0</slip1>
              <slip2>0</slip2>
            </ode>
          </friction>
        </surface>
      </collision>
    </link>

    <joint name="LeftRingDistal" type="revolute">
      <parent>LeftRingMiddle_link</parent>
      <child>LeftRingDistal_link</child>
      <axis>
        <xyz>0 -1 0</xyz>
        <limit>
          <lower>-1.48353</lower>
          <upper>-0.122173</upper>
          <velocity>0.174533</velocity>
        </limit>
        <dynamics>
          <damping>0.001</damping>
          <friction>0.7</friction>
        </dynamics>
      </axis>
    </joint>

    <link name="LeftMiddleProximal_link">
      <pose relative_to="LeftWrist_link">0.01154 0.001 -0.221 1.5708 1.5708 3.1416</pose>
      <inertial>
        <mass>0.1</mass>
      </inertial>
      <visual name="LeftMiddleProximal_visual">
        <geometry>
          <mesh>
            <scale>0.001 0.001 0.001</scale>
            <uri>model://teo_dextra/meshes/visual/Proximal.dae</uri>
          </mesh>
        </geometry>
        <material>
          <ambient>0.792157 0.819608 0.933333 1</ambient>
          <diffuse>0.792157 0.819608 0.933333 1</diffuse>
          <specular>0.633726 0.655686 0.746667 1</specular>
        </material>
      </visual>
      <collision name="LeftMiddleProximal_collision">
        <geometry>
          <mesh>
            <scale>0.001 0.001 0.001</scale>
            <uri>model://teo_dextra/meshes/collision/Proximal.stl</uri>
          </mesh>
        </geometry>
        <max_contacts>2</max_contacts>
        <surface>
          <contact>
            <ode>
              <kp>1000000</kp>
              <kd>100</kd>
              <max_vel>0.001</max_vel>
              <min_depth>0.001</min_depth>
            </ode>
          </contact>
          <friction>
            <ode>
              <mu>1</mu>
              <mu2>1</mu2>
              <slip1>0</slip1>
              <slip2>0</slip2>
            </ode>
          </friction>
        </surface>
      </collision>
    </link>

    <joint name="LeftMiddleProximal" type="revolute">
      <parent>LeftWrist_link</parent>
      <child>LeftMiddleProximal_link</child>
      <axis>
        <xyz>0 -1 0</xyz>
        <limit>
          <lower>-1.48353</lower>
          <upper>-0.122173</upper>
          <velocity>0.174533</velocity>
        </limit>
        <dynamics>
          <damping>0.001</damping>
          <friction>0.7</friction>
        </dynamics>
      </axis>
    </joint>

    <link name="LeftMiddleMiddle_link">
      <pose relative_to="LeftMiddleProximal_link">0.035 0 0 0 0 0</pose>
      <inertial>
        <mass>0.1</mass>
      </inertial>
      <visual name="LeftMiddleMiddle_visual">
        <geometry>
          <mesh>
            <scale>0.001 0.001 0.001</scale>
            <uri>model://teo_dextra/meshes/visual/Middle.dae</uri>
          </mesh>
        </geometry>
        <material>
          <ambient>0.792157 0.819608 0.933333 1</ambient>
          <diffuse>0.792157 0.819608 0.933333 1</diffuse>
          <specular>0.633726 0.655686 0.746667 1</specular>
        </material>
      </visual>
      <collision name="LeftMiddleMiddle_collision">
        <geometry>
          <mesh>
            <scale>0.001 0.001 0.001</scale>
            <uri>model://teo_dextra/meshes/collision/Middle.stl</uri>
          </mesh>
        </geometry>
        <max_contacts>2</max_contacts>
        <surface>
          <contact>
            <ode>
              <kp>1000000</kp>
              <kd>100</kd>
              <max_vel>0.001</max_vel>
              <min_depth>0.001</min_depth>
            </ode>
          </contact>
          <friction>
            <ode>
              <mu>1</mu>
              <mu2>1</mu2>
              <slip1>0</slip1>
              <slip2>0</slip2>
            </ode>
          </friction>
        </surface>
      </collision>
    </link>

    <joint name="LeftMiddleMiddle" type="revolute">
      <parent>LeftMiddleProximal_link</parent>
      <child>LeftMiddleMiddle_link</child>
      <axis>
        <xyz>0 -1 0</xyz>
        <limit>
          <lower>-1.48353</lower>
          <upper>-0.122173</upper>
          <velocity>0.174533</velocity>
        </limit>
        <dynamics>
          <damping>0.001</damping>
          <friction>0.7</friction>
        </dynamics>
      </axis>
    </joint>

    <link name="LeftMiddleDistal_link">
      <pose relative_to="LeftMiddleMiddle_link">0.025 0 0 0 0 0</pose>
      <inertial>
        <mass>0.1</mass>
      </inertial>
      <visual name="LeftMiddleDistal_visual">
        <geometry>
          <mesh>
            <scale>0.001 0.001 0.001</scale>
            <uri>model://teo_dextra/meshes/visual/Distal.dae</uri>
          </mesh>
        </geometry>
        <material>
          <ambient>0.792157 0.819608 0.933333 1</ambient>
          <diffuse>0.792157 0.819608 0.933333 1</diffuse>
          <specular>0.633726 0.655686 0.746667 1</specular>
        </material>
      </visual>
      <collision name="LeftMiddleDistal_collision">
        <geometry>
          <mesh>
            <scale>0.001 0.001 0.001</scale>
            <uri>model://teo_dextra/meshes/collision/Distal.stl</uri>
          </mesh>
        </geometry>
        <max_contacts>2</max_contacts>
        <surface>
          <contact>
            <ode>
              <kp>1000000</kp>
              <kd>100</kd>
              <max_vel>0.001</max_vel>
              <min_depth>0.001</min_depth>
            </ode>
          </contact>
          <friction>
            <ode>
              <mu>1</mu>
              <mu2>1</mu2>
              <slip1>0</slip1>
              <slip2>0</slip2>
            </ode>
          </friction>
        </surface>
      </collision>
    </link>

    <joint name="LeftMiddleDistal" type="revolute">
      <parent>LeftMiddleMiddle_link</parent>
      <child>LeftMiddleDistal_link</child>
      <axis>
        <xyz>0 -1 0</xyz>
        <limit>
          <lower>-1.48353</lower>
          <upper>-0.122173</upper>
          <velocity>0.174533</velocity>
        </limit>
        <dynamics>
          <damping>0.001</damping>
          <friction>0.7</friction>
        </dynamics>
      </axis>
    </joint>

    <link name="LeftIndexProximal_link">
      <pose relative_to="LeftWrist_link">0.03106 0.001 -0.213 1.5708 1.5708 3.1416</pose>
      <inertial>
        <mass>0.1</mass>
      </inertial>
      <visual name="LeftIndexProximal_visual">
        <geometry>
          <mesh>
            <scale>0.001 0.001 0.001</scale>
            <uri>model://teo_dextra/meshes/visual/Proximal.dae</uri>
          </mesh>
        </geometry>
        <material>
          <ambient>0.792157 0.819608 0.933333 1</ambient>
          <diffuse>0.792157 0.819608 0.933333 1</diffuse>
          <specular>0.633726 0.655686 0.746667 1</specular>
        </material>
      </visual>
      <collision name="LeftIndexProximal_collision">
        <geometry>
          <mesh>
            <scale>0.001 0.001 0.001</scale>
            <uri>model://teo_dextra/meshes/collision/Proximal.stl</uri>
          </mesh>
        </geometry>
        <max_contacts>2</max_contacts>
        <surface>
          <contact>
            <ode>
              <kp>1000000</kp>
              <kd>100</kd>
              <max_vel>0.001</max_vel>
              <min_depth>0.001</min_depth>
            </ode>
          </contact>
          <friction>
            <ode>
              <mu>1</mu>
              <mu2>1</mu2>
              <slip1>0</slip1>
              <slip2>0</slip2>
            </ode>
          </friction>
        </surface>
      </collision>
    </link>

    <joint name="LeftIndexProximal" type="revolute">
      <parent>LeftWrist_link</parent>
      <child>LeftIndexProximal_link</child>
      <axis>
        <xyz>0 -1 0</xyz>
        <limit>
          <lower>-1.48353</lower>
          <upper>-0.122173</upper>
          <velocity>0.174533</velocity>
        </limit>
        <dynamics>
          <damping>0.001</damping>
          <friction>0.7</friction>
        </dynamics>
      </axis>
    </joint>

    <link name="LeftIndexMiddle_link">
      <pose relative_to="LeftIndexProximal_link">0.035 0 0 0 0 0</pose>
      <inertial>
        <mass>0.1</mass>
      </inertial>
      <visual name="LeftIndexMiddle_visual">
        <geometry>
          <mesh>
            <scale>0.001 0.001 0.001</scale>
            <uri>model://teo_dextra/meshes/visual/Middle.dae</uri>
          </mesh>
        </geometry>
        <material>
          <ambient>0.792157 0.819608 0.933333 1</ambient>
          <diffuse>0.792157 0.819608 0.933333 1</diffuse>
          <specular>0.633726 0.655686 0.746667 1</specular>
        </material>
      </visual>
      <collision name="LeftIndexMiddle_collision">
        <geometry>
          <mesh>
            <scale>0.001 0.001 0.001</scale>
            <uri>model://teo_dextra/meshes/collision/Middle.stl</uri>
          </mesh>
        </geometry>
        <max_contacts>2</max_contacts>
        <surface>
          <contact>
            <ode>
              <kp>1000000</kp>
              <kd>100</kd>
              <max_vel>0.001</max_vel>
              <min_depth>0.001</min_depth>
            </ode>
          </contact>
          <friction>
            <ode>
              <mu>1</mu>
              <mu2>1</mu2>
              <slip1>0</slip1>
              <slip2>0</slip2>
            </ode>
          </friction>
        </surface>
      </collision>
    </link>

    <joint name="LeftIndexMiddle" type="revolute">
      <parent>LeftIndexProximal_link</parent>
      <child>LeftIndexMiddle_link</child>
      <axis>
        <xyz>0 -1 0</xyz>
        <limit>
          <lower>-1.48353</lower>
          <upper>-0.122173</upper>
          <velocity>0.174533</velocity>
        </limit>
        <dynamics>
          <damping>0.001</damping>
          <friction>0.7</friction>
        </dynamics>
      </axis>
    </joint>

    <link name="LeftIndexDistal_link">
      <pose relative_to="LeftIndexMiddle_link">0.025 0 0 0 0 0</pose>
      <inertial>
        <mass>0.1</mass>
      </inertial>
      <visual name="LeftIndexDistal_visual">
        <geometry>
          <mesh>
            <scale>0.001 0.001 0.001</scale>
            <uri>model://teo_dextra/meshes/visual/Distal.dae</uri>
          </mesh>
        </geometry>
        <material>
          <ambient>0.792157 0.819608 0.933333 1</ambient>
          <diffuse>0.792157 0.819608 0.933333 1</diffuse>
          <specular>0.633726 0.655686 0.746667 1</specular>
        </material>
      </visual>
      <collision name="LeftIndexDistal_collision">
        <geometry>
          <mesh>
            <scale>0.001 0.001 0.001</scale>
            <uri>model://teo_dextra/meshes/collision/Distal.stl</uri>
          </mesh>
        </geometry>
        <max_contacts>2</max_contacts>
        <surface>
          <contact>
            <ode>
              <kp>1000000</kp>
              <kd>100</kd>
              <max_vel>0.001</max_vel>
              <min_depth>0.001</min_depth>
            </ode>
          </contact>
          <friction>
            <ode>
              <mu>1</mu>
              <mu2>1</mu2>
              <slip1>0</slip1>
              <slip2>0</slip2>
            </ode>
          </friction>
        </surface>
      </collision>
    </link>

    <joint name="LeftIndexDistal" type="revolute">
      <parent>LeftIndexMiddle_link</parent>
      <child>LeftIndexDistal_link</child>
      <axis>
        <xyz>0 -1 0</xyz>
        <limit>
          <lower>-1.48353</lower>
          <upper>-0.122173</upper>
          <velocity>0.174533</velocity>
        </limit>
        <dynamics>
          <damping>0.001</damping>
          <friction>0.7</friction>
        </dynamics>
      </axis>
    </joint>

    <plugin name="gzyarp::ControlBoard" filename="gz-sim-yarp-controlboard-system">
      <yarpConfigurationFile>model://teo_dextra/conf/gazebo_teo_leftHand.ini</yarpConfigurationFile>
    </plugin>

  </model>
</sdf>
